[2025-03-27T04:36:20.238+0000] {local_task_job_runner.py:123} INFO - ::group::Pre task execution logs
[2025-03-27T04:36:20.257+0000] {taskinstance.py:2614} INFO - Dependencies all met for dep_context=non-requeueable deps ti=<TaskInstance: construction_web_scraping_v01.scrape_and_store manual__2025-03-27T04:31:57.775870+00:00 [queued]>
[2025-03-27T04:36:20.269+0000] {taskinstance.py:2614} INFO - Dependencies all met for dep_context=requeueable deps ti=<TaskInstance: construction_web_scraping_v01.scrape_and_store manual__2025-03-27T04:31:57.775870+00:00 [queued]>
[2025-03-27T04:36:20.270+0000] {taskinstance.py:2867} INFO - Starting attempt 2 of 7
[2025-03-27T04:36:20.286+0000] {taskinstance.py:2890} INFO - Executing <Task(PythonOperator): scrape_and_store> on 2025-03-27 04:31:57.775870+00:00
[2025-03-27T04:36:20.292+0000] {standard_task_runner.py:72} INFO - Started process 828 to run task
[2025-03-27T04:36:20.295+0000] {standard_task_runner.py:104} INFO - Running: ['***', 'tasks', 'run', 'construction_web_scraping_v01', 'scrape_and_store', 'manual__2025-03-27T04:31:57.775870+00:00', '--job-id', '27', '--raw', '--subdir', 'DAGS_FOLDER/construction_web_scraping.py', '--cfg-path', '/tmp/tmpqk0zq591']
[2025-03-27T04:36:20.299+0000] {standard_task_runner.py:105} INFO - Job 27: Subtask scrape_and_store
[2025-03-27T04:36:20.352+0000] {task_command.py:467} INFO - Running <TaskInstance: construction_web_scraping_v01.scrape_and_store manual__2025-03-27T04:31:57.775870+00:00 [running]> on host c79bd584e644
[2025-03-27T04:36:20.450+0000] {taskinstance.py:3134} INFO - Exporting env vars: AIRFLOW_CTX_DAG_OWNER='waiyong' AIRFLOW_CTX_DAG_ID='construction_web_scraping_v01' AIRFLOW_CTX_TASK_ID='scrape_and_store' AIRFLOW_CTX_EXECUTION_DATE='2025-03-27T04:31:57.775870+00:00' AIRFLOW_CTX_TRY_NUMBER='2' AIRFLOW_CTX_DAG_RUN_ID='manual__2025-03-27T04:31:57.775870+00:00'
[2025-03-27T04:36:20.451+0000] {taskinstance.py:732} INFO - ::endgroup::
[2025-03-27T04:36:20.475+0000] {logging_mixin.py:190} INFO - Scraping page 1...
[2025-03-27T04:36:34.678+0000] {logging_mixin.py:190} INFO - Scraping page 2...
[2025-03-27T04:36:50.168+0000] {logging_mixin.py:190} INFO - Scraping page 3...
[2025-03-27T04:37:08.917+0000] {logging_mixin.py:190} INFO - Scraping page 4...
[2025-03-27T04:37:22.682+0000] {logging_mixin.py:190} INFO - Scraping page 5...
[2025-03-27T04:37:36.090+0000] {logging_mixin.py:190} INFO - Columns before rename: ['BIL.', 'KOD PROJEK', 'PEMAJU', 'PROJEK', 'NO. PERMIT', 'STATUS PROJEK KESELURUHAN', 'RINGKASAN PROJEK', 'Daerah Projek', 'Negeri Projek', 'Harga Minimum (RM)', 'Harga Maksimum (RM)']
[2025-03-27T04:37:36.120+0000] {logging_mixin.py:190} INFO -   Bil  ...                                  RINGKASAN PROJEK
0   1  ...  https://teduh.kpkt.gov.my/project-swasta/30969-1
1   2  ...  https://teduh.kpkt.gov.my/project-swasta/30946-1
2   3  ...  https://teduh.kpkt.gov.my/project-swasta/30937-1
3   4  ...  https://teduh.kpkt.gov.my/project-swasta/30921-1
4   5  ...  https://teduh.kpkt.gov.my/project-swasta/30920-1
5   6  ...  https://teduh.kpkt.gov.my/project-swasta/30914-1
6   7  ...  https://teduh.kpkt.gov.my/project-swasta/30913-1
7   8  ...  https://teduh.kpkt.gov.my/project-swasta/30909-1
8   9  ...  https://teduh.kpkt.gov.my/project-swasta/30908-1
9  10  ...  https://teduh.kpkt.gov.my/project-swasta/30902-1

[10 rows x 11 columns]
[2025-03-27T04:37:36.150+0000] {logging_mixin.py:190} INFO - SQL dump created: /tmp/teduh_dump.sql
[2025-03-27T04:37:36.153+0000] {connectionpool.py:868} WARNING - Retrying (Retry(total=4, connect=None, read=None, redirect=None, status=None)) after connection broken by 'NewConnectionError('<urllib3.connection.HTTPConnection object at 0x7fca68e59330>: Failed to establish a new connection: [Errno 111] Connection refused')': /construction-web-scraping?location=
[2025-03-27T04:37:36.556+0000] {connectionpool.py:868} WARNING - Retrying (Retry(total=3, connect=None, read=None, redirect=None, status=None)) after connection broken by 'NewConnectionError('<urllib3.connection.HTTPConnection object at 0x7fca68e58700>: Failed to establish a new connection: [Errno 111] Connection refused')': /construction-web-scraping?location=
[2025-03-27T04:37:37.360+0000] {connectionpool.py:868} WARNING - Retrying (Retry(total=2, connect=None, read=None, redirect=None, status=None)) after connection broken by 'NewConnectionError('<urllib3.connection.HTTPConnection object at 0x7fca68e58f70>: Failed to establish a new connection: [Errno 111] Connection refused')': /construction-web-scraping?location=
[2025-03-27T04:37:38.964+0000] {connectionpool.py:868} WARNING - Retrying (Retry(total=1, connect=None, read=None, redirect=None, status=None)) after connection broken by 'NewConnectionError('<urllib3.connection.HTTPConnection object at 0x7fca68e58b50>: Failed to establish a new connection: [Errno 111] Connection refused')': /construction-web-scraping?location=
[2025-03-27T04:37:42.169+0000] {connectionpool.py:868} WARNING - Retrying (Retry(total=0, connect=None, read=None, redirect=None, status=None)) after connection broken by 'NewConnectionError('<urllib3.connection.HTTPConnection object at 0x7fca68e59f60>: Failed to establish a new connection: [Errno 111] Connection refused')': /construction-web-scraping?location=
[2025-03-27T04:37:42.172+0000] {taskinstance.py:3313} ERROR - Task failed with exception
Traceback (most recent call last):
  File "/home/airflow/.local/lib/python3.10/site-packages/urllib3/connection.py", line 198, in _new_conn
    sock = connection.create_connection(
  File "/home/airflow/.local/lib/python3.10/site-packages/urllib3/util/connection.py", line 85, in create_connection
    raise err
  File "/home/airflow/.local/lib/python3.10/site-packages/urllib3/util/connection.py", line 73, in create_connection
    sock.connect(sa)
ConnectionRefusedError: [Errno 111] Connection refused

The above exception was the direct cause of the following exception:

Traceback (most recent call last):
  File "/home/airflow/.local/lib/python3.10/site-packages/urllib3/connectionpool.py", line 787, in urlopen
    response = self._make_request(
  File "/home/airflow/.local/lib/python3.10/site-packages/urllib3/connectionpool.py", line 493, in _make_request
    conn.request(
  File "/home/airflow/.local/lib/python3.10/site-packages/urllib3/connection.py", line 445, in request
    self.endheaders()
  File "/usr/local/lib/python3.10/http/client.py", line 1278, in endheaders
    self._send_output(message_body, encode_chunked=encode_chunked)
  File "/usr/local/lib/python3.10/http/client.py", line 1038, in _send_output
    self.send(msg)
  File "/usr/local/lib/python3.10/http/client.py", line 976, in send
    self.connect()
  File "/home/airflow/.local/lib/python3.10/site-packages/urllib3/connection.py", line 276, in connect
    self.sock = self._new_conn()
  File "/home/airflow/.local/lib/python3.10/site-packages/urllib3/connection.py", line 213, in _new_conn
    raise NewConnectionError(
urllib3.exceptions.NewConnectionError: <urllib3.connection.HTTPConnection object at 0x7fca68e58d00>: Failed to establish a new connection: [Errno 111] Connection refused

The above exception was the direct cause of the following exception:

Traceback (most recent call last):
  File "/home/airflow/.local/lib/python3.10/site-packages/airflow/models/taskinstance.py", line 768, in _execute_task
    result = _execute_callable(context=context, **execute_callable_kwargs)
  File "/home/airflow/.local/lib/python3.10/site-packages/airflow/models/taskinstance.py", line 734, in _execute_callable
    return ExecutionCallableRunner(
  File "/home/airflow/.local/lib/python3.10/site-packages/airflow/utils/operator_helpers.py", line 252, in run
    return self.func(*args, **kwargs)
  File "/home/airflow/.local/lib/python3.10/site-packages/airflow/models/baseoperator.py", line 424, in wrapper
    return func(self, *args, **kwargs)
  File "/home/airflow/.local/lib/python3.10/site-packages/airflow/operators/python.py", line 238, in execute
    return_value = self.execute_callable()
  File "/home/airflow/.local/lib/python3.10/site-packages/airflow/operators/python.py", line 256, in execute_callable
    return runner.run(*self.op_args, **self.op_kwargs)
  File "/home/airflow/.local/lib/python3.10/site-packages/airflow/utils/operator_helpers.py", line 252, in run
    return self.func(*args, **kwargs)
  File "/opt/airflow/dags/construction_web_scraping.py", line 266, in run_scraper
    found = client.bucket_exists(MINIO_BUCKET)
  File "/home/airflow/.local/lib/python3.10/site-packages/minio/api.py", line 662, in bucket_exists
    self._execute("HEAD", bucket_name)
  File "/home/airflow/.local/lib/python3.10/site-packages/minio/api.py", line 413, in _execute
    region = self._get_region(bucket_name)
  File "/home/airflow/.local/lib/python3.10/site-packages/minio/api.py", line 470, in _get_region
    response = self._url_open(
  File "/home/airflow/.local/lib/python3.10/site-packages/minio/api.py", line 279, in _url_open
    response = self._http.urlopen(
  File "/home/airflow/.local/lib/python3.10/site-packages/urllib3/poolmanager.py", line 443, in urlopen
    response = conn.urlopen(method, u.request_uri, **kw)
  File "/home/airflow/.local/lib/python3.10/site-packages/urllib3/connectionpool.py", line 871, in urlopen
    return self.urlopen(
  File "/home/airflow/.local/lib/python3.10/site-packages/urllib3/connectionpool.py", line 871, in urlopen
    return self.urlopen(
  File "/home/airflow/.local/lib/python3.10/site-packages/urllib3/connectionpool.py", line 871, in urlopen
    return self.urlopen(
  [Previous line repeated 2 more times]
  File "/home/airflow/.local/lib/python3.10/site-packages/urllib3/connectionpool.py", line 841, in urlopen
    retries = retries.increment(
  File "/home/airflow/.local/lib/python3.10/site-packages/urllib3/util/retry.py", line 519, in increment
    raise MaxRetryError(_pool, url, reason) from reason  # type: ignore[arg-type]
urllib3.exceptions.MaxRetryError: HTTPConnectionPool(host='127.0.0.1', port=9000): Max retries exceeded with url: /construction-web-scraping?location= (Caused by NewConnectionError('<urllib3.connection.HTTPConnection object at 0x7fca68e58d00>: Failed to establish a new connection: [Errno 111] Connection refused'))
[2025-03-27T04:37:42.204+0000] {taskinstance.py:1226} INFO - Marking task as UP_FOR_RETRY. dag_id=construction_web_scraping_v01, task_id=scrape_and_store, run_id=manual__2025-03-27T04:31:57.775870+00:00, execution_date=20250327T043157, start_date=20250327T043620, end_date=20250327T043742
[2025-03-27T04:37:42.253+0000] {taskinstance.py:341} INFO - ::group::Post task execution logs
[2025-03-27T04:37:42.255+0000] {standard_task_runner.py:124} ERROR - Failed to execute job 27 for task scrape_and_store (HTTPConnectionPool(host='127.0.0.1', port=9000): Max retries exceeded with url: /construction-web-scraping?location= (Caused by NewConnectionError('<urllib3.connection.HTTPConnection object at 0x7fca68e58d00>: Failed to establish a new connection: [Errno 111] Connection refused')); 828)
Traceback (most recent call last):
  File "/home/airflow/.local/lib/python3.10/site-packages/urllib3/connection.py", line 198, in _new_conn
    sock = connection.create_connection(
  File "/home/airflow/.local/lib/python3.10/site-packages/urllib3/util/connection.py", line 85, in create_connection
    raise err
  File "/home/airflow/.local/lib/python3.10/site-packages/urllib3/util/connection.py", line 73, in create_connection
    sock.connect(sa)
ConnectionRefusedError: [Errno 111] Connection refused

The above exception was the direct cause of the following exception:

Traceback (most recent call last):
  File "/home/airflow/.local/lib/python3.10/site-packages/urllib3/connectionpool.py", line 787, in urlopen
    response = self._make_request(
  File "/home/airflow/.local/lib/python3.10/site-packages/urllib3/connectionpool.py", line 493, in _make_request
    conn.request(
  File "/home/airflow/.local/lib/python3.10/site-packages/urllib3/connection.py", line 445, in request
    self.endheaders()
  File "/usr/local/lib/python3.10/http/client.py", line 1278, in endheaders
    self._send_output(message_body, encode_chunked=encode_chunked)
  File "/usr/local/lib/python3.10/http/client.py", line 1038, in _send_output
    self.send(msg)
  File "/usr/local/lib/python3.10/http/client.py", line 976, in send
    self.connect()
  File "/home/airflow/.local/lib/python3.10/site-packages/urllib3/connection.py", line 276, in connect
    self.sock = self._new_conn()
  File "/home/airflow/.local/lib/python3.10/site-packages/urllib3/connection.py", line 213, in _new_conn
    raise NewConnectionError(
urllib3.exceptions.NewConnectionError: <urllib3.connection.HTTPConnection object at 0x7fca68e58d00>: Failed to establish a new connection: [Errno 111] Connection refused

The above exception was the direct cause of the following exception:

Traceback (most recent call last):
  File "/home/airflow/.local/lib/python3.10/site-packages/airflow/task/task_runner/standard_task_runner.py", line 117, in _start_by_fork
    ret = args.func(args, dag=self.dag)
  File "/home/airflow/.local/lib/python3.10/site-packages/airflow/cli/cli_config.py", line 49, in command
    return func(*args, **kwargs)
  File "/home/airflow/.local/lib/python3.10/site-packages/airflow/utils/cli.py", line 116, in wrapper
    return f(*args, **kwargs)
  File "/home/airflow/.local/lib/python3.10/site-packages/airflow/cli/commands/task_command.py", line 483, in task_run
    task_return_code = _run_task_by_selected_method(args, _dag, ti)
  File "/home/airflow/.local/lib/python3.10/site-packages/airflow/cli/commands/task_command.py", line 256, in _run_task_by_selected_method
    return _run_raw_task(args, ti)
  File "/home/airflow/.local/lib/python3.10/site-packages/airflow/cli/commands/task_command.py", line 341, in _run_raw_task
    return ti._run_raw_task(
  File "/home/airflow/.local/lib/python3.10/site-packages/airflow/utils/session.py", line 97, in wrapper
    return func(*args, session=session, **kwargs)
  File "/home/airflow/.local/lib/python3.10/site-packages/airflow/models/taskinstance.py", line 3006, in _run_raw_task
    return _run_raw_task(
  File "/home/airflow/.local/lib/python3.10/site-packages/airflow/models/taskinstance.py", line 274, in _run_raw_task
    TaskInstance._execute_task_with_callbacks(
  File "/home/airflow/.local/lib/python3.10/site-packages/airflow/models/taskinstance.py", line 3161, in _execute_task_with_callbacks
    result = self._execute_task(context, task_orig)
  File "/home/airflow/.local/lib/python3.10/site-packages/airflow/models/taskinstance.py", line 3185, in _execute_task
    return _execute_task(self, context, task_orig)
  File "/home/airflow/.local/lib/python3.10/site-packages/airflow/models/taskinstance.py", line 768, in _execute_task
    result = _execute_callable(context=context, **execute_callable_kwargs)
  File "/home/airflow/.local/lib/python3.10/site-packages/airflow/models/taskinstance.py", line 734, in _execute_callable
    return ExecutionCallableRunner(
  File "/home/airflow/.local/lib/python3.10/site-packages/airflow/utils/operator_helpers.py", line 252, in run
    return self.func(*args, **kwargs)
  File "/home/airflow/.local/lib/python3.10/site-packages/airflow/models/baseoperator.py", line 424, in wrapper
    return func(self, *args, **kwargs)
  File "/home/airflow/.local/lib/python3.10/site-packages/airflow/operators/python.py", line 238, in execute
    return_value = self.execute_callable()
  File "/home/airflow/.local/lib/python3.10/site-packages/airflow/operators/python.py", line 256, in execute_callable
    return runner.run(*self.op_args, **self.op_kwargs)
  File "/home/airflow/.local/lib/python3.10/site-packages/airflow/utils/operator_helpers.py", line 252, in run
    return self.func(*args, **kwargs)
  File "/opt/airflow/dags/construction_web_scraping.py", line 266, in run_scraper
    found = client.bucket_exists(MINIO_BUCKET)
  File "/home/airflow/.local/lib/python3.10/site-packages/minio/api.py", line 662, in bucket_exists
    self._execute("HEAD", bucket_name)
  File "/home/airflow/.local/lib/python3.10/site-packages/minio/api.py", line 413, in _execute
    region = self._get_region(bucket_name)
  File "/home/airflow/.local/lib/python3.10/site-packages/minio/api.py", line 470, in _get_region
    response = self._url_open(
  File "/home/airflow/.local/lib/python3.10/site-packages/minio/api.py", line 279, in _url_open
    response = self._http.urlopen(
  File "/home/airflow/.local/lib/python3.10/site-packages/urllib3/poolmanager.py", line 443, in urlopen
    response = conn.urlopen(method, u.request_uri, **kw)
  File "/home/airflow/.local/lib/python3.10/site-packages/urllib3/connectionpool.py", line 871, in urlopen
    return self.urlopen(
  File "/home/airflow/.local/lib/python3.10/site-packages/urllib3/connectionpool.py", line 871, in urlopen
    return self.urlopen(
  File "/home/airflow/.local/lib/python3.10/site-packages/urllib3/connectionpool.py", line 871, in urlopen
    return self.urlopen(
  [Previous line repeated 2 more times]
  File "/home/airflow/.local/lib/python3.10/site-packages/urllib3/connectionpool.py", line 841, in urlopen
    retries = retries.increment(
  File "/home/airflow/.local/lib/python3.10/site-packages/urllib3/util/retry.py", line 519, in increment
    raise MaxRetryError(_pool, url, reason) from reason  # type: ignore[arg-type]
urllib3.exceptions.MaxRetryError: HTTPConnectionPool(host='127.0.0.1', port=9000): Max retries exceeded with url: /construction-web-scraping?location= (Caused by NewConnectionError('<urllib3.connection.HTTPConnection object at 0x7fca68e58d00>: Failed to establish a new connection: [Errno 111] Connection refused'))
[2025-03-27T04:37:42.290+0000] {local_task_job_runner.py:266} INFO - Task exited with return code 1
[2025-03-27T04:37:42.318+0000] {taskinstance.py:3901} INFO - 0 downstream tasks scheduled from follow-on schedule check
[2025-03-27T04:37:42.321+0000] {local_task_job_runner.py:245} INFO - ::endgroup::
