[2025-03-27T08:57:37.033+0000] {local_task_job_runner.py:123} INFO - ::group::Pre task execution logs
[2025-03-27T08:57:37.061+0000] {taskinstance.py:2614} INFO - Dependencies all met for dep_context=non-requeueable deps ti=<TaskInstance: construction_web_scraping_v01.scrape_and_store scheduled__2025-03-16T00:00:00+00:00 [queued]>
[2025-03-27T08:57:37.075+0000] {taskinstance.py:2614} INFO - Dependencies all met for dep_context=requeueable deps ti=<TaskInstance: construction_web_scraping_v01.scrape_and_store scheduled__2025-03-16T00:00:00+00:00 [queued]>
[2025-03-27T08:57:37.076+0000] {taskinstance.py:2867} INFO - Starting attempt 5 of 6
[2025-03-27T08:57:37.096+0000] {taskinstance.py:2890} INFO - Executing <Task(PythonOperator): scrape_and_store> on 2025-03-16 00:00:00+00:00
[2025-03-27T08:57:37.104+0000] {standard_task_runner.py:72} INFO - Started process 7449 to run task
[2025-03-27T08:57:37.111+0000] {standard_task_runner.py:104} INFO - Running: ['***', 'tasks', 'run', 'construction_web_scraping_v01', 'scrape_and_store', 'scheduled__2025-03-16T00:00:00+00:00', '--job-id', '71', '--raw', '--subdir', 'DAGS_FOLDER/construction_web_scraping.py', '--cfg-path', '/tmp/tmptt0rsf2y']
[2025-03-27T08:57:37.115+0000] {standard_task_runner.py:105} INFO - Job 71: Subtask scrape_and_store
[2025-03-27T08:57:37.193+0000] {task_command.py:467} INFO - Running <TaskInstance: construction_web_scraping_v01.scrape_and_store scheduled__2025-03-16T00:00:00+00:00 [running]> on host c79bd584e644
[2025-03-27T08:57:37.768+0000] {taskinstance.py:3134} INFO - Exporting env vars: AIRFLOW_CTX_DAG_OWNER='waiyong' AIRFLOW_CTX_DAG_ID='construction_web_scraping_v01' AIRFLOW_CTX_TASK_ID='scrape_and_store' AIRFLOW_CTX_EXECUTION_DATE='2025-03-16T00:00:00+00:00' AIRFLOW_CTX_TRY_NUMBER='5' AIRFLOW_CTX_DAG_RUN_ID='scheduled__2025-03-16T00:00:00+00:00'
[2025-03-27T08:57:37.770+0000] {taskinstance.py:732} INFO - ::endgroup::
[2025-03-27T08:57:37.790+0000] {logging_mixin.py:190} INFO - Scraping page 1...
[2025-03-27T08:58:01.935+0000] {logging_mixin.py:190} INFO - Scraping page 2...
[2025-03-27T08:58:22.686+0000] {logging_mixin.py:190} INFO - Scraping page 3...
[2025-03-27T08:58:44.734+0000] {logging_mixin.py:190} INFO - Scraping page 4...
[2025-03-27T08:59:04.134+0000] {logging_mixin.py:190} INFO - Scraping page 5...
[2025-03-27T08:59:22.470+0000] {logging_mixin.py:190} INFO - Scraping page 6...
[2025-03-27T08:59:40.049+0000] {logging_mixin.py:190} INFO - Scraping page 7...
[2025-03-27T08:59:59.768+0000] {logging_mixin.py:190} INFO - Scraping page 8...
[2025-03-27T09:00:27.427+0000] {logging_mixin.py:190} INFO - Scraping page 9...
[2025-03-27T09:01:00.934+0000] {logging_mixin.py:190} INFO - Scraping page 10...
[2025-03-27T09:01:18.519+0000] {logging_mixin.py:190} INFO - Scraping page 11...
[2025-03-27T09:01:36.896+0000] {logging_mixin.py:190} INFO - Scraping page 12...
[2025-03-27T09:02:01.967+0000] {logging_mixin.py:190} INFO - Scraping page 13...
[2025-03-27T09:02:32.439+0000] {logging_mixin.py:190} INFO - Scraping page 14...
[2025-03-27T09:03:01.354+0000] {logging_mixin.py:190} INFO - Scraping page 15...
[2025-03-27T09:03:17.835+0000] {logging_mixin.py:190} INFO - Scraping page 16...
[2025-03-27T09:03:36.306+0000] {logging_mixin.py:190} INFO - Scraping page 17...
[2025-03-27T09:03:55.060+0000] {logging_mixin.py:190} INFO - Scraping page 18...
[2025-03-27T09:04:13.725+0000] {logging_mixin.py:190} INFO - Scraping page 19...
[2025-03-27T09:04:31.295+0000] {logging_mixin.py:190} INFO - Scraping page 20...
[2025-03-27T09:04:47.585+0000] {logging_mixin.py:190} INFO - Scraping page 21...
[2025-03-27T09:05:04.504+0000] {logging_mixin.py:190} INFO - Scraping page 22...
[2025-03-27T09:05:24.319+0000] {logging_mixin.py:190} INFO - Scraping page 23...
[2025-03-27T09:05:41.660+0000] {logging_mixin.py:190} INFO - Scraping page 24...
[2025-03-27T09:05:58.326+0000] {logging_mixin.py:190} INFO - Scraping page 25...
[2025-03-27T09:06:15.332+0000] {logging_mixin.py:190} INFO - Scraping page 26...
[2025-03-27T09:06:34.633+0000] {logging_mixin.py:190} INFO - Scraping page 27...
[2025-03-27T09:06:51.100+0000] {logging_mixin.py:190} INFO - Scraping page 28...
[2025-03-27T09:07:10.758+0000] {logging_mixin.py:190} INFO - Scraping page 29...
[2025-03-27T09:07:27.885+0000] {logging_mixin.py:190} INFO - Scraping page 30...
[2025-03-27T09:07:46.113+0000] {logging_mixin.py:190} INFO - Scraping page 31...
[2025-03-27T09:08:04.993+0000] {logging_mixin.py:190} INFO - Scraping page 32...
[2025-03-27T09:08:26.540+0000] {logging_mixin.py:190} INFO - Scraping page 33...
[2025-03-27T09:08:45.599+0000] {logging_mixin.py:190} INFO - Scraping page 34...
[2025-03-27T09:09:04.354+0000] {logging_mixin.py:190} INFO - Scraping page 35...
[2025-03-27T09:09:21.715+0000] {logging_mixin.py:190} INFO - Scraping page 36...
[2025-03-27T09:09:41.658+0000] {logging_mixin.py:190} INFO - Scraping page 37...
[2025-03-27T09:10:03.900+0000] {logging_mixin.py:190} INFO - Scraping page 38...
[2025-03-27T09:10:24.944+0000] {taskinstance.py:3313} ERROR - Task failed with exception
Traceback (most recent call last):
  File "/home/airflow/.local/lib/python3.10/site-packages/urllib3/connection.py", line 198, in _new_conn
    sock = connection.create_connection(
  File "/home/airflow/.local/lib/python3.10/site-packages/urllib3/util/connection.py", line 85, in create_connection
    raise err
  File "/home/airflow/.local/lib/python3.10/site-packages/urllib3/util/connection.py", line 73, in create_connection
    sock.connect(sa)
ConnectionRefusedError: [Errno 111] Connection refused

The above exception was the direct cause of the following exception:

Traceback (most recent call last):
  File "/home/airflow/.local/lib/python3.10/site-packages/urllib3/connectionpool.py", line 787, in urlopen
    response = self._make_request(
  File "/home/airflow/.local/lib/python3.10/site-packages/urllib3/connectionpool.py", line 488, in _make_request
    raise new_e
  File "/home/airflow/.local/lib/python3.10/site-packages/urllib3/connectionpool.py", line 464, in _make_request
    self._validate_conn(conn)
  File "/home/airflow/.local/lib/python3.10/site-packages/urllib3/connectionpool.py", line 1093, in _validate_conn
    conn.connect()
  File "/home/airflow/.local/lib/python3.10/site-packages/urllib3/connection.py", line 704, in connect
    self.sock = sock = self._new_conn()
  File "/home/airflow/.local/lib/python3.10/site-packages/urllib3/connection.py", line 213, in _new_conn
    raise NewConnectionError(
urllib3.exceptions.NewConnectionError: <urllib3.connection.HTTPSConnection object at 0x7fca68aa9f60>: Failed to establish a new connection: [Errno 111] Connection refused

The above exception was the direct cause of the following exception:

Traceback (most recent call last):
  File "/home/airflow/.local/lib/python3.10/site-packages/requests/adapters.py", line 667, in send
    resp = conn.urlopen(
  File "/home/airflow/.local/lib/python3.10/site-packages/urllib3/connectionpool.py", line 841, in urlopen
    retries = retries.increment(
  File "/home/airflow/.local/lib/python3.10/site-packages/urllib3/util/retry.py", line 519, in increment
    raise MaxRetryError(_pool, url, reason) from reason  # type: ignore[arg-type]
urllib3.exceptions.MaxRetryError: HTTPSConnectionPool(host='teduh.kpkt.gov.my', port=443): Max retries exceeded with url: /project-swasta?page=38 (Caused by NewConnectionError('<urllib3.connection.HTTPSConnection object at 0x7fca68aa9f60>: Failed to establish a new connection: [Errno 111] Connection refused'))

During handling of the above exception, another exception occurred:

Traceback (most recent call last):
  File "/home/airflow/.local/lib/python3.10/site-packages/airflow/models/taskinstance.py", line 763, in _execute_task
    result = _execute_callable(context=context, **execute_callable_kwargs)
  File "/home/airflow/.local/lib/python3.10/site-packages/airflow/models/taskinstance.py", line 734, in _execute_callable
    return ExecutionCallableRunner(
  File "/home/airflow/.local/lib/python3.10/site-packages/airflow/utils/operator_helpers.py", line 252, in run
    return self.func(*args, **kwargs)
  File "/home/airflow/.local/lib/python3.10/site-packages/airflow/models/baseoperator.py", line 424, in wrapper
    return func(self, *args, **kwargs)
  File "/home/airflow/.local/lib/python3.10/site-packages/airflow/operators/python.py", line 238, in execute
    return_value = self.execute_callable()
  File "/home/airflow/.local/lib/python3.10/site-packages/airflow/operators/python.py", line 256, in execute_callable
    return runner.run(*self.op_args, **self.op_kwargs)
  File "/home/airflow/.local/lib/python3.10/site-packages/airflow/utils/operator_helpers.py", line 252, in run
    return self.func(*args, **kwargs)
  File "/opt/airflow/dags/construction_web_scraping.py", line 172, in run_scraper
    current_headers, rows = scrape_page(page_number)
  File "/opt/airflow/dags/construction_web_scraping.py", line 131, in scrape_page
    response = requests.get(url)
  File "/home/airflow/.local/lib/python3.10/site-packages/requests/api.py", line 73, in get
    return request("get", url, params=params, **kwargs)
  File "/home/airflow/.local/lib/python3.10/site-packages/requests/api.py", line 59, in request
    return session.request(method=method, url=url, **kwargs)
  File "/home/airflow/.local/lib/python3.10/site-packages/requests/sessions.py", line 589, in request
    resp = self.send(prep, **send_kwargs)
  File "/home/airflow/.local/lib/python3.10/site-packages/requests/sessions.py", line 703, in send
    r = adapter.send(request, **kwargs)
  File "/home/airflow/.local/lib/python3.10/site-packages/requests/adapters.py", line 700, in send
    raise ConnectionError(e, request=request)
requests.exceptions.ConnectionError: HTTPSConnectionPool(host='teduh.kpkt.gov.my', port=443): Max retries exceeded with url: /project-swasta?page=38 (Caused by NewConnectionError('<urllib3.connection.HTTPSConnection object at 0x7fca68aa9f60>: Failed to establish a new connection: [Errno 111] Connection refused'))
[2025-03-27T09:10:24.973+0000] {taskinstance.py:1226} INFO - Marking task as UP_FOR_RETRY. dag_id=construction_web_scraping_v01, task_id=scrape_and_store, run_id=scheduled__2025-03-16T00:00:00+00:00, execution_date=20250316T000000, start_date=20250327T085737, end_date=20250327T091024
[2025-03-27T09:10:25.017+0000] {taskinstance.py:341} INFO - ::group::Post task execution logs
[2025-03-27T09:10:25.018+0000] {standard_task_runner.py:124} ERROR - Failed to execute job 71 for task scrape_and_store (HTTPSConnectionPool(host='teduh.kpkt.gov.my', port=443): Max retries exceeded with url: /project-swasta?page=38 (Caused by NewConnectionError('<urllib3.connection.HTTPSConnection object at 0x7fca68aa9f60>: Failed to establish a new connection: [Errno 111] Connection refused')); 7449)
Traceback (most recent call last):
  File "/home/airflow/.local/lib/python3.10/site-packages/urllib3/connection.py", line 198, in _new_conn
    sock = connection.create_connection(
  File "/home/airflow/.local/lib/python3.10/site-packages/urllib3/util/connection.py", line 85, in create_connection
    raise err
  File "/home/airflow/.local/lib/python3.10/site-packages/urllib3/util/connection.py", line 73, in create_connection
    sock.connect(sa)
ConnectionRefusedError: [Errno 111] Connection refused

The above exception was the direct cause of the following exception:

Traceback (most recent call last):
  File "/home/airflow/.local/lib/python3.10/site-packages/urllib3/connectionpool.py", line 787, in urlopen
    response = self._make_request(
  File "/home/airflow/.local/lib/python3.10/site-packages/urllib3/connectionpool.py", line 488, in _make_request
    raise new_e
  File "/home/airflow/.local/lib/python3.10/site-packages/urllib3/connectionpool.py", line 464, in _make_request
    self._validate_conn(conn)
  File "/home/airflow/.local/lib/python3.10/site-packages/urllib3/connectionpool.py", line 1093, in _validate_conn
    conn.connect()
  File "/home/airflow/.local/lib/python3.10/site-packages/urllib3/connection.py", line 704, in connect
    self.sock = sock = self._new_conn()
  File "/home/airflow/.local/lib/python3.10/site-packages/urllib3/connection.py", line 213, in _new_conn
    raise NewConnectionError(
urllib3.exceptions.NewConnectionError: <urllib3.connection.HTTPSConnection object at 0x7fca68aa9f60>: Failed to establish a new connection: [Errno 111] Connection refused

The above exception was the direct cause of the following exception:

Traceback (most recent call last):
  File "/home/airflow/.local/lib/python3.10/site-packages/requests/adapters.py", line 667, in send
    resp = conn.urlopen(
  File "/home/airflow/.local/lib/python3.10/site-packages/urllib3/connectionpool.py", line 841, in urlopen
    retries = retries.increment(
  File "/home/airflow/.local/lib/python3.10/site-packages/urllib3/util/retry.py", line 519, in increment
    raise MaxRetryError(_pool, url, reason) from reason  # type: ignore[arg-type]
urllib3.exceptions.MaxRetryError: HTTPSConnectionPool(host='teduh.kpkt.gov.my', port=443): Max retries exceeded with url: /project-swasta?page=38 (Caused by NewConnectionError('<urllib3.connection.HTTPSConnection object at 0x7fca68aa9f60>: Failed to establish a new connection: [Errno 111] Connection refused'))

During handling of the above exception, another exception occurred:

Traceback (most recent call last):
  File "/home/airflow/.local/lib/python3.10/site-packages/airflow/task/task_runner/standard_task_runner.py", line 117, in _start_by_fork
    ret = args.func(args, dag=self.dag)
  File "/home/airflow/.local/lib/python3.10/site-packages/airflow/cli/cli_config.py", line 49, in command
    return func(*args, **kwargs)
  File "/home/airflow/.local/lib/python3.10/site-packages/airflow/utils/cli.py", line 116, in wrapper
    return f(*args, **kwargs)
  File "/home/airflow/.local/lib/python3.10/site-packages/airflow/cli/commands/task_command.py", line 483, in task_run
    task_return_code = _run_task_by_selected_method(args, _dag, ti)
  File "/home/airflow/.local/lib/python3.10/site-packages/airflow/cli/commands/task_command.py", line 256, in _run_task_by_selected_method
    return _run_raw_task(args, ti)
  File "/home/airflow/.local/lib/python3.10/site-packages/airflow/cli/commands/task_command.py", line 341, in _run_raw_task
    return ti._run_raw_task(
  File "/home/airflow/.local/lib/python3.10/site-packages/airflow/utils/session.py", line 97, in wrapper
    return func(*args, session=session, **kwargs)
  File "/home/airflow/.local/lib/python3.10/site-packages/airflow/models/taskinstance.py", line 3006, in _run_raw_task
    return _run_raw_task(
  File "/home/airflow/.local/lib/python3.10/site-packages/airflow/models/taskinstance.py", line 274, in _run_raw_task
    TaskInstance._execute_task_with_callbacks(
  File "/home/airflow/.local/lib/python3.10/site-packages/airflow/models/taskinstance.py", line 3161, in _execute_task_with_callbacks
    result = self._execute_task(context, task_orig)
  File "/home/airflow/.local/lib/python3.10/site-packages/airflow/models/taskinstance.py", line 3185, in _execute_task
    return _execute_task(self, context, task_orig)
  File "/home/airflow/.local/lib/python3.10/site-packages/airflow/models/taskinstance.py", line 763, in _execute_task
    result = _execute_callable(context=context, **execute_callable_kwargs)
  File "/home/airflow/.local/lib/python3.10/site-packages/airflow/models/taskinstance.py", line 734, in _execute_callable
    return ExecutionCallableRunner(
  File "/home/airflow/.local/lib/python3.10/site-packages/airflow/utils/operator_helpers.py", line 252, in run
    return self.func(*args, **kwargs)
  File "/home/airflow/.local/lib/python3.10/site-packages/airflow/models/baseoperator.py", line 424, in wrapper
    return func(self, *args, **kwargs)
  File "/home/airflow/.local/lib/python3.10/site-packages/airflow/operators/python.py", line 238, in execute
    return_value = self.execute_callable()
  File "/home/airflow/.local/lib/python3.10/site-packages/airflow/operators/python.py", line 256, in execute_callable
    return runner.run(*self.op_args, **self.op_kwargs)
  File "/home/airflow/.local/lib/python3.10/site-packages/airflow/utils/operator_helpers.py", line 252, in run
    return self.func(*args, **kwargs)
  File "/opt/airflow/dags/construction_web_scraping.py", line 172, in run_scraper
    current_headers, rows = scrape_page(page_number)
  File "/opt/airflow/dags/construction_web_scraping.py", line 131, in scrape_page
    response = requests.get(url)
  File "/home/airflow/.local/lib/python3.10/site-packages/requests/api.py", line 73, in get
    return request("get", url, params=params, **kwargs)
  File "/home/airflow/.local/lib/python3.10/site-packages/requests/api.py", line 59, in request
    return session.request(method=method, url=url, **kwargs)
  File "/home/airflow/.local/lib/python3.10/site-packages/requests/sessions.py", line 589, in request
    resp = self.send(prep, **send_kwargs)
  File "/home/airflow/.local/lib/python3.10/site-packages/requests/sessions.py", line 703, in send
    r = adapter.send(request, **kwargs)
  File "/home/airflow/.local/lib/python3.10/site-packages/requests/adapters.py", line 700, in send
    raise ConnectionError(e, request=request)
requests.exceptions.ConnectionError: HTTPSConnectionPool(host='teduh.kpkt.gov.my', port=443): Max retries exceeded with url: /project-swasta?page=38 (Caused by NewConnectionError('<urllib3.connection.HTTPSConnection object at 0x7fca68aa9f60>: Failed to establish a new connection: [Errno 111] Connection refused'))
[2025-03-27T09:10:25.037+0000] {local_task_job_runner.py:266} INFO - Task exited with return code 1
[2025-03-27T09:10:25.064+0000] {taskinstance.py:3901} INFO - 0 downstream tasks scheduled from follow-on schedule check
[2025-03-27T09:10:25.068+0000] {local_task_job_runner.py:245} INFO - ::endgroup::
